Traceback (most recent call last):
  File "/home/cpigg2/my-envs/py3/lib/python3.6/site-packages/urllib3/connectionpool.py", line 387, in _make_request
    six.raise_from(e, None)
  File "<string>", line 2, in raise_from
  File "/home/cpigg2/my-envs/py3/lib/python3.6/site-packages/urllib3/connectionpool.py", line 383, in _make_request
    httplib_response = conn.getresponse()
  File "/home/cpigg2/my-envs/py3/lib/python3.6/http/client.py", line 1331, in getresponse
    response.begin()
  File "/home/cpigg2/my-envs/py3/lib/python3.6/http/client.py", line 297, in begin
    version, status, reason = self._read_status()
  File "/home/cpigg2/my-envs/py3/lib/python3.6/http/client.py", line 258, in _read_status
    line = str(self.fp.readline(_MAXLINE + 1), "iso-8859-1")
  File "/home/cpigg2/my-envs/py3/lib/python3.6/socket.py", line 586, in readinto
    return self._sock.recv_into(b)
  File "/home/cpigg2/my-envs/py3/lib/python3.6/ssl.py", line 1002, in recv_into
    return self.read(nbytes, buffer)
  File "/home/cpigg2/my-envs/py3/lib/python3.6/ssl.py", line 865, in read
    return self._sslobj.read(len, buffer)
  File "/home/cpigg2/my-envs/py3/lib/python3.6/ssl.py", line 625, in read
    v = self._sslobj.read(len, buffer)
socket.timeout: The read operation timed out

During handling of the above exception, another exception occurred:

Traceback (most recent call last):
  File "/home/cpigg2/my-envs/py3/lib/python3.6/site-packages/requests/adapters.py", line 440, in send
    timeout=timeout
  File "/home/cpigg2/my-envs/py3/lib/python3.6/site-packages/urllib3/connectionpool.py", line 639, in urlopen
    _stacktrace=sys.exc_info()[2])
  File "/home/cpigg2/my-envs/py3/lib/python3.6/site-packages/urllib3/util/retry.py", line 357, in increment
    raise six.reraise(type(error), error, _stacktrace)
  File "/home/cpigg2/my-envs/py3/lib/python3.6/site-packages/urllib3/packages/six.py", line 686, in reraise
    raise value
  File "/home/cpigg2/my-envs/py3/lib/python3.6/site-packages/urllib3/connectionpool.py", line 601, in urlopen
    chunked=chunked)
  File "/home/cpigg2/my-envs/py3/lib/python3.6/site-packages/urllib3/connectionpool.py", line 389, in _make_request
    self._raise_timeout(err=e, url=url, timeout_value=read_timeout)
  File "/home/cpigg2/my-envs/py3/lib/python3.6/site-packages/urllib3/connectionpool.py", line 309, in _raise_timeout
    raise ReadTimeoutError(self, url, "Read timed out. (read timeout=%s)" % timeout_value)
urllib3.exceptions.ReadTimeoutError: HTTPSConnectionPool(host='api.exmo.com', port=443): Read timed out. (read timeout=10)

During handling of the above exception, another exception occurred:

Traceback (most recent call last):
  File "/home/cpigg2/my-envs/py3/lib/python3.6/site-packages/ccxt/base/exchange.py", line 360, in fetch
    proxies=self.proxies
  File "/home/cpigg2/my-envs/py3/lib/python3.6/site-packages/requests/sessions.py", line 508, in request
    resp = self.send(prep, **send_kwargs)
  File "/home/cpigg2/my-envs/py3/lib/python3.6/site-packages/requests/sessions.py", line 618, in send
    r = adapter.send(request, **kwargs)
  File "/home/cpigg2/my-envs/py3/lib/python3.6/site-packages/requests/adapters.py", line 521, in send
    raise ReadTimeout(e, request=request)
requests.exceptions.ReadTimeout: HTTPSConnectionPool(host='api.exmo.com', port=443): Read timed out. (read timeout=10)

During handling of the above exception, another exception occurred:

Traceback (most recent call last):
  File "simulation.py", line 153, in <module>
    # sim.start_simulation()
  File "simulation.py", line 105, in start_simulation
    if not self.place_paper_order():
  File "simulation.py", line 63, in place_paper_order
    order = self.get_order()
  File "simulation.py", line 56, in get_order
    sell_info = self.get_to_sell()
  File "simulation.py", line 42, in get_to_sell
    orders0 = self.exchange0.fetch_order_book(self.symbol)
  File "/home/cpigg2/my-envs/py3/lib/python3.6/site-packages/ccxt/exmo.py", line 151, in fetch_order_book
    }, params))
  File "/home/cpigg2/my-envs/py3/lib/python3.6/site-packages/ccxt/exmo.py", line 308, in request
    response = self.fetch2(path, api, method, params, headers, body)
  File "/home/cpigg2/my-envs/py3/lib/python3.6/site-packages/ccxt/base/exchange.py", line 308, in fetch2
    return self.fetch(request['url'], request['method'], request['headers'], request['body'])
  File "/home/cpigg2/my-envs/py3/lib/python3.6/site-packages/ccxt/base/exchange.py", line 367, in fetch
    raise RequestTimeout(' '.join([self.id, method, url, 'request timeout']))
ccxt.base.errors.RequestTimeout: exmo GET https://api.exmo.com/v1/order_book?pair=BTC_USDT request timeout
